<?xml version="1.0" encoding="UTF-8"?>
<!-- Generated by org.testng.reporters.JUnitXMLReporter -->
<testsuite hostname="PMUFTWIN101" ignored="2" name="TestNG Suite Tests(failed)" tests="1" failures="1" timestamp="19 Nov 2018 10:53:29 GMT" time="1.018" errors="0">
  <testcase name="method1_in_Class1_in_package2" time="0.815" classname="package2.Class1">
    <failure type="java.lang.ArithmeticException">
      <![CDATA[java.lang.ArithmeticException
at package2.Class1.method1_in_Class1_in_package2(Class1.java:31)
at java.util.concurrent.FutureTask.run(FutureTask.java:266)
at java.util.concurrent.ThreadPoolExecutor.runWorker(ThreadPoolExecutor.java:1142)
at java.util.concurrent.ThreadPoolExecutor$Worker.run(ThreadPoolExecutor.java:617)
at java.lang.Thread.run(Thread.java:745)
... Removed 16 stack frames]]>
    </failure>
  </testcase> <!-- method1_in_Class1_in_package2 -->
  <testcase name="method3_in_Class1_in_package2" time="0.0" classname="package2.Class1">
    <ignored/>
  </testcase> <!-- method3_in_Class1_in_package2 -->
  <testcase name="method2_in_Class1_in_package2" time="0.0" classname="package2.Class1">
    <ignored/>
  </testcase> <!-- method2_in_Class1_in_package2 -->
</testsuite> <!-- TestNG Suite Tests(failed) -->
